<?xml version="1.0"?>

<robot name="robot">

<!--   Colors   -->

    <material name="black">
        <color rgba="0 0 0 1"/>
    </material>

    <material name="white">
        <color rgba="1 1 1 1"/>
    </material>

    <material name="silver">
        <color rgba="0.75 0.75 0.75 1"/>
    </material>

    <material name="yellow">
        <color rgba="0.95 1 0 1"/>
    </material>

    <material name="blue">
        <color rgba="0 0 1 1"/>
    </material>

    <material name="gray">
        <color rgba="0.4 0.4 0.4 1"/>
    </material>

    <material name="green">
        <color rgba="0 1 0 1"/>
    </material>

<!--   Links  -->

<!--   Base   -->

    <link name="base_footprint">
        <visual>
            <geometry>
                <box size="0.040 0.025 0"/>
            </geometry>
            <origin rpy="0 0 0" xyz="0 0 0"/>
        </visual>
    </link>

    <link name="base_link">
        <visual>
            <geometry>
                <box size="0.300 0.200 0.012"/>
            </geometry>
            <origin rpy="0 0 0" xyz="0 0 0"/>
            <material name="blue"/>
        </visual>
    </link>
    
<!--   Wheels   -->

    <link name="wheel_left_gear">
        <visual>
            <geometry>
                <box size="0.058 0.036 0.040"/>
            </geometry>
            <origin rpy="0 0 0" xyz="0 0 0"/>
            <material name="silver"/>
        </visual>
    </link>

    <link name="wheel_left_motor">
        <visual>
            <geometry>
                <cylinder length="0.068" radius="0.016"/>
            </geometry>
            <origin rpy="0 1.57079 0" xyz="0 0 0"/>
            <material name="black"/>
        </visual>
    </link>

    <link name="wheel_left_shaft">
        <visual>
            <geometry>
                <cylinder length="0.032" radius="0.012"/>
            </geometry>
            <origin rpy="1.57079 0 0" xyz="0 0 0"/>
            <material name="silver"/>
        </visual>    
    </link>

    <link name="wheel_left">
        <visual>
            <geometry>
                <cylinder length="0.026" radius="0.076"/>
            </geometry>
            <origin rpy="1.57079 0 0" xyz="0 0 0"/>
            <material name="white"/>
        </visual>    
    </link>

    <link name="wheel_left_marker">
        <visual>
            <geometry>
                <box size="0.002 0.002 0.030"/>
            </geometry>
            <origin rpy="0 0 0" xyz="0 0 0"/>
            <material name="yellow"/>
        </visual>    
    </link>

    <link name="wheel_right_gear">
        <visual>
            <geometry>
                <box size="0.058 0.036 0.040"/>
            </geometry>
            <origin rpy="0 0 0" xyz="0 0 0"/>
            <material name="silver"/>
        </visual>    
    </link>

    <link name="wheel_right_motor">
        <visual>
            <geometry>
                <cylinder length="0.068" radius="0.016"/>
            </geometry>
            <origin rpy="0 1.57079 0" xyz="0 0 0"/>
            <material name="black"/>
        </visual>    
    </link>

    <link name="wheel_right_shaft">
        <visual>
            <geometry>
                <cylinder length="0.032" radius="0.012"/>
            </geometry>
            <origin rpy="1.57079 0 0" xyz="0 0 0"/>
            <material name="silver"/>
        </visual>    
    </link>

    <link name="wheel_right">
        <visual>
            <geometry>
                <cylinder length="0.026" radius="0.076"/>
            </geometry>
            <origin rpy="1.57079 0 0" xyz="0 0 0"/>
            <material name="white"/>
        </visual>    
    </link>

    <link name="wheel_right_marker">
        <visual>
            <geometry>
                <box size="0.002 0.002 0.030"/>
            </geometry>
            <origin rpy="0 0 0" xyz="0 0 0"/>
            <material name="yellow"/>
        </visual>    
    </link>

<!--   Caster   -->

    <link name="caster_wheel">
        <visual>
            <geometry>
                <cylinder length="0.032" radius="0.050"/>
            </geometry>
            <origin rpy="1.57079 0 0" xyz="0 0 0"/>
            <material name="gray"/>
        </visual>
    </link>
    
<!--   Electronics   -->

    <link name="elec_rasp_pi">
        <visual>
            <geometry>
                <box size="0.055 0.080 0.002"/>
            </geometry>
            <origin rpy="0 0 0" xyz="0 0 0"/>
            <material name="green"/>
        </visual>
    </link>

    <link name="elec_driver">
        <visual>
            <geometry>
                <box size="0.060 0.090 0.002"/>
            </geometry>
            <origin rpy="0 0 0" xyz="0 0 0"/>
            <material name="green"/>
        </visual>
    </link>

    <link name="imu_link">
        <visual>
            <geometry>
                <box size="0.020 0.028 0.002"/>
            </geometry>
            <origin rpy="0 0 0" xyz="0 0 0"/>
            <material name="blue"/>
        </visual>
    </link>

    <link name="gps_link">
        <visual>
            <geometry>
                <box size="0.026 0.035 0.002"/>
            </geometry>
            <origin rpy="0 0 0" xyz="0 0 0"/>
            <material name="blue"/>
        </visual>
    </link>

    <link name="elec_sabertooth">
        <visual>
            <geometry>
                <box size="0.090 0.075 0.002"/>
            </geometry>
            <origin rpy="0 0 0" xyz="0 0 0"/>
            <material name="green"/>
        </visual>
    </link>

<!--   Battery   -->

    <link name="bat_lead">
        <visual>
            <geometry>
                <box size="0.065 0.151 0.095"/>
            </geometry>
            <origin rpy="0 0 0" xyz="0 0 0"/>
            <material name="black"/>
        </visual>
    </link>

    <link name="bat_lithium">
        <visual>
            <geometry>
                <box size="0.019 0.152 0.074"/>
            </geometry>
            <origin rpy="0 0 0" xyz="0 0 0"/>
            <material name="black"/>
        </visual>
    </link>

<!--   Camera   -->

    <link name="camera_base">
        <visual>
            <geometry>
                <box size="0.050 0.100 0.006"/>
            </geometry>
            <origin rpy="0 0 0" xyz="0 0 0"/>
            <material name="blue"/>
        </visual>
    </link>

    <link name="camera_post">
        <visual>
            <geometry>
                <cylinder length="0.012" radius="0.008"/>
            </geometry>
            <origin rpy="0 0 0" xyz="0 0 0"/>
            <material name="black"/>
        </visual>
    </link>

    <link name="camera_link">
        <visual>
            <geometry>
                <sphere radius="0.025"/>
            </geometry>
            <origin rpy="0 0 0" xyz="0 0 0"/>
            <material name="black"/>
        </visual>
    </link>

<!--   Joints   -->

<!--   Base     -->

    <joint name="base_footprint_link" type="fixed">
        <origin rpy="0 0 0" xyz="-0.065 0 0.146"/>
        <parent link="base_footprint"/>
        <child link="base_link"/>
    </joint>

<!--   Wheels   -->

    <joint name="base_left_gear" type="fixed">
        <origin rpy="0 2.35619 3.14159" xyz="0.050 0.130 -0.070"/>
        <parent link="base_link"/>
        <child link="wheel_left_gear"/>
    </joint>
    
    <joint name="gear_left_motor" type="fixed">
        <origin rpy="0 0 0" xyz="-0.063 0.002 0"/>
        <parent link="wheel_left_gear"/>
        <child link="wheel_left_motor"/>
    </joint>
    
    <joint name="gear_left_shaft" type="continuous">
        <origin rpy="0 0 0" xyz="0.015 -0.034 0"/>
        <parent link="wheel_left_gear"/>
        <child link="wheel_left_shaft"/>
        <axis xyz="0 -1 0"/>
    </joint>
    
    <joint name="shaft_left_wheel" type="fixed">
        <origin rpy="0 0 0" xyz="0 -0.029 0"/>
        <parent link="wheel_left_shaft"/>
        <child link="wheel_left"/>
    </joint>
    
    <joint name="wheel_left_marker" type="fixed">
        <origin rpy="0 0 0" xyz="0 -0.013 0.061"/>
        <parent link="wheel_left"/>
        <child link="wheel_left_marker"/>
    </joint>

    <joint name="base_right_gear" type="fixed">
        <origin rpy="0 0.70711 0" xyz="0.050 -0.130 -0.070"/>
        <parent link="base_link"/>
        <child link="wheel_right_gear"/>
    </joint>
    
    <joint name="gear_right_motor" type="fixed">
        <origin rpy="0 0 0" xyz="-0.063 0.002 0"/>
        <parent link="wheel_right_gear"/>
        <child link="wheel_right_motor"/>
    </joint>
    
    <joint name="gear_right_shaft" type="continuous">
        <origin rpy="0 0 0" xyz="0.015 -0.034 0"/>
        <parent link="wheel_right_gear"/>
        <child link="wheel_right_shaft"/>
        <axis xyz="0 1 0"/>
    </joint>
    
    <joint name="shaft_right_wheel" type="fixed">
        <origin rpy="0 0 0" xyz="0 -0.029 0"/>
        <parent link="wheel_right_shaft"/>
        <child link="wheel_right"/>
    </joint>
    
    <joint name="wheel_right_marker" type="fixed">
        <origin rpy="0 0 0" xyz="0 -0.013 0.061"/>
        <parent link="wheel_right"/>
        <child link="wheel_right_marker"/>
    </joint>

<!--   Caster   -->

    <joint name="base_caster_wheel" type="fixed">
        <origin rpy="0 0 0" xyz="-0.150 0 -0.085"/>
        <parent link="base_link"/>
        <child link="caster_wheel"/>
    </joint>

<!--   Electronics   -->

    <joint name="base_rasp_pi" type="fixed">
        <origin rpy="0 0 0" xyz="-0.100 -0.012 0.015"/>
        <parent link="base_link"/>
        <child link="elec_rasp_pi"/>
    </joint>

    <joint name="rasp_pi_driver" type="fixed">
        <origin rpy="0 0 0" xyz="-0.100 0.008 0.030"/>
        <parent link="base_link"/>
        <child link="elec_driver"/>
    </joint>

    <joint name="driver_imu" type="fixed">
        <origin rpy="0 0 0" xyz="-0.020 0.005 0.015"/>
        <parent link="elec_driver"/>
        <child link="imu_link"/>
    </joint>

    <joint name="driver_gps" type="fixed">
        <origin rpy="0 0 0" xyz="0 -0.028 0.015"/>
        <parent link="elec_driver"/>
        <child link="gps_link"/>
    </joint>

    <joint name="base_sabertooth" type="fixed">
        <origin rpy="0 0 0" xyz="0.099 0 0.008"/>
        <parent link="base_link"/>
        <child link="elec_sabertooth"/>
    </joint>

<!--   Battery   -->

    <joint name="base_bat_lead" type="fixed">
        <origin rpy="0 0 0" xyz="0 0 0.046"/>
        <parent link="base_link"/>
        <child link="bat_lead"/>
    </joint>

    <joint name="base_bat_lithium" type="fixed">
        <origin rpy="0 0 0" xyz="-0.042 0 0.037"/>
        <parent link="base_link"/>
        <child link="bat_lithium"/>
    </joint>

<!--   Camera   -->

    <joint name="base_camera_base" type="fixed">
        <origin rpy="0 0 0" xyz="0.118 0 0.080"/>
        <parent link="base_link"/>
        <child link="camera_base"/>
    </joint>

    <joint name="camera_base_post" type="fixed">
        <origin rpy="0 0 0" xyz="0 0 0.006"/>
        <parent link="camera_base"/>
        <child link="camera_post"/>
    </joint>

    <joint name="post_camera" type="fixed">
        <origin rpy="0 0 0" xyz="0 0 0.031"/>
        <parent link="camera_post"/>
        <child link="camera_link"/>
    </joint>

<!--   ROS2 Control tags   -->

    <ros2_control name="teensy_control" type="system">

        <hardware>
            <plugin>topic_based_ros2_control/TopicBasedSystem</plugin>
            <param name="joint_commands_topic">/arduino/commands</param>
            <param name="joint_states_topic">/arduino/joint_states</param>
            <param name="trigger_joint_command_threshold">-1.0</param>
        </hardware>

        <joint name="gear_left_shaft">
            <command_interface name="velocity"/>
            <state_interface name="position">
                <param name="initial_value">0.0</param>
            </state_interface>
            <state_interface name="velocity"/>
        </joint>

        <joint name="gear_right_shaft">
            <command_interface name="velocity"/>
            <state_interface name="position">
                <param name="initial_value">0.0</param>
            </state_interface>
            <state_interface name="velocity"/>
        </joint>

    </ros2_control>

</robot>

